Workbook

Sheet all_data
B1: P0 | C1: P1 | D1: P2 | E1: P3 | F1: P4 | G1: P5 | H1: P6 | I1: P7 | J1: P8 | K1: P9 | L1: P10 | M1: P11 | N1: P12 | O1: P13 | P1: P14 | Q1: P15 | R1: P16 | S1: P17 | T1: P18 | U1: P19 | V1: P20 | W1: P21 | X1: P22 | Y1: P23 | Z1: P24 | AA1: P25 | AB1: P26 | AC1: P27 | AD1: P28 | AE1: P29 | AF1: P30 | AG1: P31 | AH1: P32 | AI1: P33 | AJ1: P34 | AK1: P35 | AL1: P36 | AM1: P37 | AN1: P38 | AO1: P39 | AP1: E0 - 600 | AT1: E1 - 600 | AX1: E2 - 600 | BB1: E3 - 600 | BF1: E4 - 600 | BJ1: E5 | BN1: E6 | BR1: E7 | BV1: E8 | BZ1: E9 | CD1: E10 | CH1: E11 | CL1: E12 | CP1: E13 | CT1: E14 | CX1: E15 | DB1: E16 | DF1: E17 | DJ1: E18 | DN1: E19 | DR1: E20 | DV1: E21 | DZ1: E22 | ED1: E23 | EH1: E24 | EL1: E25 | EP1: E26 | ET1: E27 | EX1: E28 | FB1: E29 | FF1: E30 | FJ1: E31 | FN1: E32 | FR1: E33 | FV1: E34 | FZ1: E35 - 600 | GD1: E36 - 600 | GH1: E37 - 600 | GL1: E38 - 600 | GP1: E39 - 600
A2: Index [1] | B2: Temperature [C] | C2: Temperature [C] | D2: Temperature [C] | E2: Temperature [C] | F2: Temperature [C] | G2: Temperature [C] | H2: Temperature [C] | I2: Temperature [C] | J2: Temperature [C] | K2: Temperature [C] | L2: Temperature [C] | M2: Temperature [C] | N2: Temperature [C] | O2: Temperature [C] | P2: Temperature [C] | Q2: Temperature [C] | R2: Temperature [C] | S2: Temperature [C] | T2: Temperature [C] | U2: Temperature [C] | V2: Temperature [C] | W2: Temperature [C] | X2: Temperature [C] | Y2: Temperature [C] | Z2: Temperature [C] | AA2: Temperature [C] | AB2: Temperature [C] | AC2: Temperature [C] | AD2: Temperature [C] | AE2: Temperature [C] | AF2: Temperature [C] | AG2: Temperature [C] | AH2: Temperature [C] | AI2: Temperature [C] | AJ2: Temperature [C] | AK2: Temperature [C] | AL2: Temperature [C] | AM2: Temperature [C] | AN2: Temperature [C] | AO2: Temperature [C] | AP2: ΔL/L0 [1] | AQ2: ΔL [mm] | AR2: L1 [mm] | AS2: L0 [mm] | AT2: ΔL/L0 [1] | AU2: ΔL [mm] | AV2: L1 [mm] | AW2: L0 [mm] | AX2: ΔL/L0 [1] | AY2: ΔL [mm] | AZ2: L1 [mm] | BA2: L0 [mm] | BB2: ΔL/L0 [1] | BC2: ΔL [mm] | BD2: L1 [mm] | BE2: L0 [mm] | BF2: ΔL/L0 [1] | BG2: ΔL [mm] | BH2: L1 [mm] | BI2: L0 [mm] | BJ2: ΔL/L0 [1] | BK2: ΔL [mm] | BL2: L1 [mm] | BM2: L0 [mm] | BN2: ΔL/L0 [1] | BO2: ΔL [mm] | BP2: L1 [mm] | BQ2: L0 [mm] | BR2: ΔL/L0 [1] | BS2: ΔL [mm] | BT2: L1 [mm] | BU2: L0 [mm] | BV2: ΔL/L0 [1] | BW2: ΔL [mm] | BX2: L1 [mm] | BY2: L0 [mm] | BZ2: ΔL/L0 [1] | CA2: ΔL [mm] | CB2: L1 [mm] | CC2: L0 [mm] | CD2: ΔL/L0 [1] | CE2: ΔL [mm] | CF2: L1 [mm] | CG2: L0 [mm] | CH2: ΔL/L0 [1] | CI2: ΔL [mm] | CJ2: L1 [mm] | CK2: L0 [mm] | CL2: ΔL/L0 [1] | CM2: ΔL [mm] | CN2: L1 [mm] | CO2: L0 [mm] | CP2: ΔL/L0 [1] | CQ2: ΔL [mm] | CR2: L1 [mm] | CS2: L0 [mm] | CT2: ΔL/L0 [1] | CU2: ΔL [mm] | CV2: L1 [mm] | CW2: L0 [mm] | CX2: ΔL/L0 [1] | CY2: ΔL [mm] | CZ2: L1 [mm] | DA2: L0 [mm] | DB2: ΔL/L0 [1] | DC2: ΔL [mm] | DD2: L1 [mm] | DE2: L0 [mm] | DF2: ΔL/L0 [1] | DG2: ΔL [mm] | DH2: L1 [mm] | DI2: L0 [mm] | DJ2: ΔL/L0 [1] | DK2: ΔL [mm] | DL2: L1 [mm] | DM2: L0 [mm] | DN2: ΔL/L0 [1] | DO2: ΔL [mm] | DP2: L1 [mm] | DQ2: L0 [mm] | DR2: ΔL/L0 [1] | DS2: ΔL [mm] | DT2: L1 [mm] | DU2: L0 [mm] | DV2: ΔL/L0 [1] | DW2: ΔL [mm] | DX2: L1 [mm] | DY2: L0 [mm] | DZ2: ΔL/L0 [1] | EA2: ΔL [mm] | EB2: L1 [mm] | EC2: L0 [mm] | ED2: ΔL/L0 [1] | EE2: ΔL [mm] | EF2: L1 [mm] | EG2: L0 [mm] | EH2: ΔL/L0 [1] | EI2: ΔL [mm] | EJ2: L1 [mm] | EK2: L0 [mm] | EL2: ΔL/L0 [1] | EM2: ΔL [mm] | EN2: L1 [mm] | EO2: L0 [mm] | EP2: ΔL/L0 [1] | EQ2: ΔL [mm] | ER2: L1 [mm] | ES2: L0 [mm] | ET2: ΔL/L0 [1] | EU2: ΔL [mm] | EV2: L1 [mm] | EW2: L0 [mm] | EX2: ΔL/L0 [1] | EY2: ΔL [mm] | EZ2: L1 [mm] | FA2: L0 [mm] | FB2: ΔL/L0 [1] | FC2: ΔL [mm] | FD2: L1 [mm] | FE2: L0 [mm] | FF2: ΔL/L0 [1] | FG2: ΔL [mm] | FH2: L1 [mm] | FI2: L0 [mm] | FJ2: ΔL/L0 [1] | FK2: ΔL [mm] | FL2: L1 [mm] | FM2: L0 [mm] | FN2: ΔL/L0 [1] | FO2: ΔL [mm] | FP2: L1 [mm] | FQ2: L0 [mm] | FR2: ΔL/L0 [1] | FS2: ΔL [mm] | FT2: L1 [mm] | FU2: L0 [mm] | FV2: ΔL/L0 [1] | FW2: ΔL [mm] | FX2: L1 [mm] | FY2: L0 [mm] | FZ2: ΔL/L0 [1] | GA2: ΔL [mm] | GB2: L1 [mm] | GC2: L0 [mm] | GD2: ΔL/L0 [1] | GE2: ΔL [mm] | GF2: L1 [mm] | GG2: L0 [mm] | GH2: ΔL/L0 [1] | GI2: ΔL [mm] | GJ2: L1 [mm] | GK2: L0 [mm] | GL2: ΔL/L0 [1] | GM2: ΔL [mm] | GN2: L1 [mm] | GO2: L0 [mm] | GP2: ΔL/L0 [1] | GQ2: ΔL [mm] | GR2: L1 [mm] | GS2: L0 [mm]
A3: 0 | B3: 599.855 | C3: 600.18 | D3: 599.458 | E3: 599.921 | F3: 599.732 | G3: 574.314 | H3: 575.55 | I3: 575.445 | J3: 574.903 | K3: 575.195 | L3: 550.44 | M3: 550.316 | N3: 550.946 | O3: 550.768 | P3: 550.885 | Q3: 525.134 | R3: 525.092 | S3: 525.094 | T3: 525.063 | U3: 525.199 | V3: 575.049 | W3: 575.007 | X3: 575.012 | Y3: 575.063 | Z3: 575.042 | AA3: 550.001 | AB3: 550.08 | AC3: 550.032 | AD3: 550.503 | AE3: 550.037 | AF3: 525.018 | AG3: 525.02 | AH3: 525.818 | AI3: 525.003 | AJ3: 525.014 | AK3: 600.011 | AL3: 599.875 | AM3: 599.68 | AN3: 599.796 | AO3: 600.163 | AP3: 0 | AQ3: 0 | AR3: 0.379477 | AS3: 0.379477 | AT3: 0 | AU3: 0 | AV3: 0.380422 | AW3: 0.380422 | AX3: 0 | AY3: 0 | AZ3: 0.380442 | BA3: 0.380442 | BB3: 0 | BC3: 0 | BD3: 0.380467 | BE3: 0.380467 | BF3: 0 | BG3: 0 | BH3: 0.380061 | BI3: 0.380061 | BJ3: 0 | BK3: 0 | BL3: 0.380516 | BM3: 0.380516 | BN3: 0 | BO3: 0 | BP3: 0.380594 | BQ3: 0.380594 | BR3: 0 | BS3: 0 | BT3: 0.380277 | BU3: 0.380277 | BV3: 0 | BW3: 0 | BX3: 0.380006 | BY3: 0.380006 | BZ3: 0 | CA3: 0 | CB3: 0.38002 | CC3: 0.38002 | CD3: 0 | CE3: 0 | CF3: 0.379919 | CG3: 0.379919 | CH3: 0 | CI3: 0 | CJ3: 0.380169 | CK3: 0.380169 | CL3: 0 | CM3: 0 | CN3: 0.380216 | CO3: 0.380216 | CP3: 0 | CQ3: 0 | CR3: 0.380509 | CS3: 0.380509 | CT3: 0 | CU3: 0 | CV3: 0.380709 | CW3: 0.380709 | CX3: 0 | CY3: 0 | CZ3: 0.380196 | DA3: 0.380196 | DB3: 0 | DC3: 0 | DD3: 0.380355 | DE3: 0.380355 | DF3: 0 | DG3: 0 | DH3: 0.380234 | DI3: 0.380234 | DJ3: 0 | DK3: 0 | DL3: 0.380537 | DM3: 0.380537 | DN3: 0 | DO3: 0 | DP3: 0.380274 | DQ3: 0.380274 | DR3: 0 | DS3: 0 | DT3: 0.379769 | DU3: 0.379769 | DV3: 0 | DW3: 0 | DX3: 0.380531 | DY3: 0.380531 | DZ3: 0 | EA3: 0 | EB3: 0.379864 | EC3: 0.379864 | ED3: 0 | EE3: 0 | EF3: 0.380256 | EG3: 0.380256 | EH3: 0 | EI3: 0 | EJ3: 0.380425 | EK3: 0.380425 | EL3: 0 | EM3: 0 | EN3: 0.380266 | EO3: 0.380266 | EP3: 0 | EQ3: 0 | ER3: 0.380063 | ES3: 0.380063 | ET3: 0 | EU3: 0 | EV3: 0.380151 | EW3: 0.380151 | EX3: 0 | EY3: 0 | EZ3: 0.380965 | FA3: 0.380965 | FB3: 0 | FC3: 0 | FD3: 0.380444 | FE3: 0.380444 | FF3: 0 | FG3: 0 | FH3: 0.360571 | FI3: 0.360571 | FJ3: 0 | FK3: 0 | FL3: 0.38046 | FM3: 0.38046 | FN3: 0 | FO3: 0 | FP3: 0.380033 | FQ3: 0.380033 | FR3: 0 | FS3: 0 | FT3: 0.380133 | FU3: 0.380133 | FV3: 0 | FW3: 0 | FX3: 0.380522 | FY3: 0.380522 | FZ3: 0 | GA3: 0 | GB3: 0.379661 | GC3: 0.379661 | GD3: 0 | GE3: 0 | GF3: 0.379951 | GG3: 0.379951 | GH3: 0 | GI3: 0 | GJ3: 0.38086 | GK3: 0.38086 | GL3: 0 | GM3: 0 | GN3: 0.380355 | GO3: 0.380355 | GP3: 0 | GQ3: 0 | GR3: 0.379958 | GS3: 0.379958
A4: 1 | B4: 599.94 | C4: 600.374 | D4: 599.537 | E4: 600.045 | F4: 599.891 | G4: 574.659 | H4: 575.72 | I4: 575.499 | J4: 575.119 | K4: 575.399 | L4: 550.683 | M4: 550.754 | N4: 551.005 | O4: 550.917 | P4: 551.057 | Q4: 525.377 | R4: 525.337 | S4: 525.37 | T4: 525.217 | U4: 525.473 | V4: 575.105 | W4: 574.972 | X4: 574.965 | Y4: 574.919 | Z4: 575.109 | AA4: 550.021 | AB4: 550.117 | AC4: 549.964 | AD4: 550.527 | AE4: 549.937 | AF4: 525.044 | AG4: 525.001 | AH4: 525.741 | AI4: 524.974 | AJ4: 524.945 | AK4: 600.143 | AL4: 599.842 | AM4: 599.634 | AN4: 599.896 | AO4: 600.271 | AP4: -9.8174e-06 | AQ4: -3.72547e-06 | AR4: 0.379473 | AS4: 0.379477 | AT4: 0.000491383 | AU4: 0.000186933 | AV4: 0.380609 | AW4: 0.380422 | AX4: 0.000760679 | AY4: 0.000289394 | AZ4: 0.380731 | BA4: 0.380442 | BB4: -0.000120421 | BC4: -4.58162e-05 | BD4: 0.380422 | BE4: 0.380467 | BF4: 0.000377364 | BG4: 0.000143421 | BH4: 0.380204 | BI4: 0.380061 | BJ4: 0.000176876 | BK4: 6.73042e-05 | BL4: 0.380584 | BM4: 0.380516 | BN4: 0.000115682 | BO4: 4.40279e-05 | BP4: 0.380638 | BQ4: 0.380594 | BR4: 0.000250082 | BS4: 9.51006e-05 | BT4: 0.380372 | BU4: 0.380277 | BV4: -0.000283525 | BW4: -0.000107741 | BX4: 0.379898 | BY4: 0.380006 | BZ4: -5.24436e-05 | CA4: -1.99296e-05 | CB4: 0.38 | CC4: 0.38002 | CD4: -0.000175131 | CE4: -6.65356e-05 | CF4: 0.379852 | CG4: 0.379919 | CH4: -7.91193e-05 | CI4: -3.00787e-05 | CJ4: 0.380139 | CK4: 0.380169 | CL4: 0.00013559 | CM4: 5.15533e-05 | CN4: 0.380268 | CO4: 0.380216 | CP4: -0.000323677 | CQ4: -0.000123162 | CR4: 0.380386 | CS4: 0.380509 | CT4: 0.000192626 | CU4: 7.33344e-05 | CV4: 0.380782 | CW4: 0.380709 | CX4: 0.000451814 | CY4: 0.000171778 | CZ4: 0.380367 | DA4: 0.380196 | DB4: -7.60714e-05 | DC4: -2.89341e-05 | DD4: 0.380326 | DE4: 0.380355 | DF4: 0.000174387 | DG4: 6.63077e-05 | DH4: 0.3803 | DI4: 0.380234 | DJ4: 0.000400976 | DK4: 0.000152586 | DL4: 0.38069 | DM4: 0.380537 | DN4: 0.000547922 | DO4: 0.000208361 | DP4: 0.380483 | DQ4: 0.380274 | DR4: -6.77147e-05 | DS4: -2.57159e-05 | DT4: 0.379743 | DU4: 0.379769 | DV4: -6.44124e-06 | DW4: -2.45109e-06 | DX4: 0.380528 | DY4: 0.380531 | DZ4: 6.91056e-05 | EA4: 2.62507e-05 | EB4: 0.37989 | EC4: 0.379864 | ED4: 6.56764e-05 | EE4: 2.49738e-05 | EF4: 0.380281 | EG4: 0.380256 | EH4: -5.45782e-05 | EI4: -2.07629e-05 | EJ4: 0.380404 | EK4: 0.380425 | EL4: -0.000357074 | EM4: -0.000135783 | EN4: 0.38013 | EO4: 0.380266 | EP4: 0.000296131 | EQ4: 0.000112548 | ER4: 0.380175 | ES4: 0.380063 | ET4: 0.000218295 | EU4: 8.29853e-05 | EV4: 0.380234 | EW4: 0.380151 | EX4: -0.000193056 | EY4: -7.35473e-05 | EZ4: 0.380891 | FA4: 0.380965 | FB4: 0.00045646 | FC4: 0.000173658 | FD4: 0.380618 | FE4: 0.380444 | FF4: 0.000591629 | FG4: 0.000213324 | FH4: 0.360784 | FI4: 0.360571 | FJ4: -0.000115584 | FK4: -4.3975e-05 | FL4: 0.380416 | FM4: 0.38046 | FN4: -0.000350105 | FO4: -0.000133052 | FP4: 0.3799 | FQ4: 0.380033 | FR4: -0.000268612 | FS4: -0.000102108 | FT4: 0.380031 | FU4: 0.380133 | FV4: 7.2071e-05 | FW4: 2.74246e-05 | FX4: 0.38055 | FY4: 0.380522 | FZ4: 9.2086e-05 | GA4: 3.49615e-05 | GB4: 0.379696 | GC4: 0.379661 | GD4: -0.000121672 | GE4: -4.62292e-05 | GF4: 0.379905 | GG4: 0.379951 | GH4: 8.97826e-05 | GI4: 3.41946e-05 | GJ4: 0.380894 | GK4: 0.38086 | GL4: -8.43401e-05 | GM4: -3.20792e-05 | GN4: 0.380323 | GO4: 0.380355 | GP4: 3.44271e-05 | GQ4: 1.30809e-05 | GR4: 0.379971 | GS4: 0.379958
A5: 2 | B5: 599.906 | C5: 600.524 | D5: 600.167 | E5: 600.319 | F5: 600.169 | G5: 574.586 | H5: 575.602 | I5: 575.539 | J5: 575.001 | K5: 575.365 | L5: 550.551 | M5: 550.367 | N5: 550.911 | O5: 550.967 | P5: 551.022 | Q5: 525.18 | R5: 525.193 | S5: 525.222 | T5: 525.05 | U5: 525.382 | V5: 575.605 | W5: 575.517 | X5: 575.508 | Y5: 575.584 | Z5: 575.531 | AA5: 550.564 | AB5: 550.587 | AC5: 550.638 | AD5: 551.003 | AE5: 550.591 | AF5: 525.578 | AG5: 525.66 | AH5: 526.334 | AI5: 525.573 | AJ5: 525.64 | AK5: 600.311 | AL5: 600.116 | AM5: 600.06 | AN5: 600.3 | AO5: 600.597 | AP5: 0.000117935 | AQ5: 4.47536e-05 | AR5: 0.379521 | AS5: 0.379477 | AT5: 0.000527873 | AU5: 0.000200814 | AV5: 0.380623 | AW5: 0.380422 | AX5: 0.000657871 | AY5: 0.000250281 | AZ5: 0.380692 | BA5: 0.380442 | BB5: 0.000142197 | BC5: 5.41013e-05 | BD5: 0.380521 | BE5: 0.380467 | BF5: 0.000668719 | BG5: 0.000254154 | BH5: 0.380315 | BI5: 0.380061 | BJ5: 0.000551436 | BK5: 0.00020983 | BL5: 0.380726 | BM5: 0.380516 | BN5: 0.000483139 | BO5: 0.00018388 | BP5: 0.380778 | BQ5: 0.380594 | BR5: 0.00049821 | BS5: 0.000189458 | BT5: 0.380467 | BU5: 0.380277 | BV5: -0.000183666 | BW5: -6.97942e-05 | BX5: 0.379936 | BY5: 0.380006 | BZ5: -5.2952e-05 | CA5: -2.01228e-05 | CB5: 0.38 | CC5: 0.38002 | CD5: 0.000127784 | CE5: 4.85476e-05 | CF5: 0.379967 | CG5: 0.379919 | CH5: 0.000357807 | CI5: 0.000136027 | CJ5: 0.380305 | CK5: 0.380169 | CL5: 0.000369046 | CM5: 0.000140317 | CN5: 0.380356 | CO5: 0.380216 | CP5: -0.000359642 | CQ5: -0.000136847 | CR5: 0.380372 | CS5: 0.380509 | CT5: 0.000208992 | CU5: 7.95651e-05 | CV5: 0.380788 | CW5: 0.380709 | CX5: 0.000475906 | CY5: 0.000180937 | CZ5: 0.380377 | DA5: 0.380196 | DB5: -0.000177417 | DC5: -6.74812e-05 | DD5: 0.380287 | DE5: 0.380355 | DF5: 0.000349511 | DG5: 0.000132896 | DH5: 0.380367 | DI5: 0.380234 | DJ5: 0.000334916 | DK5: 0.000127448 | DL5: 0.380665 | DM5: 0.380537 | DN5: 0.000167939 | DO5: 6.38629e-05 | DP5: 0.380338 | DQ5: 0.380274 | DR5: 0.000594934 | DS5: 0.000225937 | DT5: 0.379995 | DU5: 0.379769 | DV5: 0.000605845 | DW5: 0.000230543 | DX5: 0.380761 | DY5: 0.380531 | DZ5: 0.000739235 | EA5: 0.000280809 | EB5: 0.380145 | EC5: 0.379864 | ED5: 0.00071245 | EE5: 0.000270913 | EF5: 0.380527 | EG5: 0.380256 | EH5: 0.000626669 | EI5: 0.000238401 | EJ5: 0.380663 | EK5: 0.380425 | EL5: 6.74277e-05 | EM5: 2.56405e-05 | EN5: 0.380291 | EO5: 0.380266 | EP5: 0.000532394 | EQ5: 0.000202343 | ER5: 0.380265 | ES5: 0.380063 | ET5: 0.000502217 | EU5: 0.000190919 | EV5: 0.380342 | EW5: 0.380151 | EX5: 0.000543467 | EY5: 0.000207042 | EZ5: 0.381172 | FA5: 0.380965 | FB5: 0.000570885 | FC5: 0.00021719 | FD5: 0.380661 | FE5: 0.380444 | FF5: 0.000348364 | FG5: 0.00012561 | FH5: 0.360697 | FI5: 0.360571 | FJ5: 0.000165175 | FK5: 6.28424e-05 | FL5: 0.380523 | FM5: 0.38046 | FN5: -0.000100677 | FO5: -3.82606e-05 | FP5: 0.379995 | FQ5: 0.380033 | FR5: 0.000195081 | FS5: 7.41565e-05 | FT5: 0.380207 | FU5: 0.380133 | FV5: 0.000475127 | FW5: 0.000180797 | FX5: 0.380703 | FY5: 0.380522 | FZ5: 0.000231738 | GA5: 8.79819e-05 | GB5: 0.379749 | GC5: 0.379661 | GD5: 0.000492284 | GE5: 0.000187044 | GF5: 0.380138 | GG5: 0.379951 | GH5: 0.000700582 | GI5: 0.000266823 | GJ5: 0.381127 | GK5: 0.38086 | GL5: 0.000795344 | GM5: 0.000302514 | GN5: 0.380658 | GO5: 0.380355 | GP5: 0.000626149 | GQ5: 0.00023791 | GR5: 0.380196 | GS5: 0.379958
A6: 3 | B6: 599.861 | C6: 600.441 | D6: 600.03 | E6: 600.206 | F6: 600.062 | G6: 574.957 | H6: 575.914 | I6: 575.832 | J6: 575.492 | K6: 575.702 | L6: 551.112 | M6: 551.206 | N6: 551.579 | O6: 551.548 | P6: 551.727 | Q6: 525.933 | R6: 525.953 | S6: 526.112 | T6: 525.926 | U6: 526.197 | V6: 575.04 | W6: 575.061 | X6: 575.12 | Y6: 575.236 | Z6: 575.289 | AA6: 550.237 | AB6: 550.24 | AC6: 550.182 | AD6: 550.635 | AE6: 550.215 | AF6: 525.293 | AG6: 525.291 | AH6: 525.926 | AI6: 525.26 | AJ6: 525.275 | AK6: 600.05 | AL6: 599.821 | AM6: 599.734 | AN6: 600.042 | AO6: 600.378 | AP6: 0.00031252 | AQ6: 0.000118594 | AR6: 0.379595 | AS6: 0.379477 | AT6: 0.000521143 | AU6: 0.000198254 | AV6: 0.38062 | AW6: 0.380422 | AX6: 0.00074411 | AY6: 0.000283091 | AZ6: 0.380725 | BA6: 0.380442 | BB6: 0.000538677 | BC6: 0.000204949 | BD6: 0.380672 | BE6: 0.380467 | BF6: 0.00120336 | BG6: 0.000457348 | BH6: 0.380518 | BI6: 0.380061 | BJ6: 8.93433e-05 | BK6: 3.39966e-05 | BL6: 0.38055 | BM6: 0.380516 | BN6: 0.000176147 | BO6: 6.70406e-05 | BP6: 0.380661 | BQ6: 0.380594 | BR6: 0.000471841 | BS6: 0.00017943 | BT6: 0.380457 | BU6: 0.380277 | BV6: -4.91042e-05 | BW6: -1.86599e-05 | BX6: 0.379987 | BY6: 0.380006 | BZ6: -3.10687e-05 | CA6: -1.18067e-05 | CB6: 0.380008 | CC6: 0.38002 | CD6: -0.000262788 | CE6: -9.98382e-05 | CF6: 0.379819 | CG6: 0.379919 | CH6: 0.000454434 | CI6: 0.000172762 | CJ6: 0.380342 | CK6: 0.380169 | CL6: 0.000260132 | CM6: 9.89064e-05 | CN6: 0.380315 | CO6: 0.380216 | CP6: -0.000319288 | CQ6: -0.000121492 | CR6: 0.380387 | CS6: 0.380509 | CT6: 0.000653959 | CU6: 0.000248968 | CV6: 0.380958 | CW6: 0.380709 | CX6: 0.00066438 | CY6: 0.000252595 | CZ6: 0.380448 | DA6: 0.380196 | DB6: 0.000184682 | DC6: 7.02445e-05 | DD6: 0.380425 | DE6: 0.380355 | DF6: -9.57261e-05 | DG6: -3.63983e-05 | DH6: 0.380198 | DI6: 0.380234 | DJ6: 0.000567719 | DK6: 0.000216038 | DL6: 0.380753 | DM6: 0.380537 | DN6: 0.000399112 | DO6: 0.000151772 | DP6: 0.380426 | DQ6: 0.380274 | DR6: 0.000547643 | DS6: 0.000207978 | DT6: 0.379977 | DU6: 0.379769 | DV6: 0.000390433 | DW6: 0.000148572 | DX6: 0.380679 | DY6: 0.380531 | DZ6: 0.000660645 | EA6: 0.000250955 | EB6: 0.380115 | EC6: 0.379864 | ED6: 0.000566975 | EE6: 0.000215596 | EF6: 0.380471 | EG6: 0.380256 | EH6: 0.00060888 | EI6: 0.000231633 | EJ6: 0.380657 | EK6: 0.380425 | EL6: -0.000226168 | EM6: -8.6004e-05 | EN6: 0.38018 | EO6: 0.380266 | EP6: -8.96659e-05 | EQ6: -3.40787e-05 | ER6: 0.380029 | ES6: 0.380063 | ET6: 0.000250677 | EU6: 9.52952e-05 | EV6: 0.380247 | EW6: 0.380151 | EX6: -0.000196539 | EY6: -7.48745e-05 | EZ6: 0.38089 | FA6: 0.380965 | FB6: 0.000390837 | FC6: 0.000148692 | FD6: 0.380593 | FE6: 0.380444 | FF6: 5.07224e-05 | FG6: 1.8289e-05 | FH6: 0.360589 | FI6: 0.360571 | FJ6: 0.000262536 | FK6: 9.98846e-05 | FL6: 0.38056 | FM6: 0.38046 | FN6: -0.000262551 | FO6: -9.9778e-05 | FP6: 0.379934 | FQ6: 0.380033 | FR6: -5.72173e-05 | FS6: -2.17502e-05 | FT6: 0.380111 | FU6: 0.380133 | FV6: 8.46468e-05 | FW6: 3.221e-05 | FX6: 0.380554 | FY6: 0.380522 | FZ6: 0.000417287 | GA6: 0.000158428 | GB6: 0.37982 | GC6: 0.379661 | GD6: 0.000619256 | GE6: 0.000235287 | GF6: 0.380186 | GG6: 0.379951 | GH6: 0.00072572 | GI6: 0.000276397 | GJ6: 0.381136 | GK6: 0.38086 | GL6: 0.000868747 | GM6: 0.000330433 | GN6: 0.380686 | GO6: 0.380355 | GP6: 0.00076269 | GQ6: 0.000289791 | GR6: 0.380248 | GS6: 0.379958
A7: 4 | B7: 599.702 | C7: 600.267 | D7: 599.867 | E7: 599.891 | F7: 599.785 | G7: 574.018 | H7: 575.139 | I7: 574.95 | J7: 574.59 | K7: 574.878 | L7: 549.795 | M7: 549.928 | N7: 550.23 | O7: 550.052 | P7: 550.264 | Q7: 524.089 | R7: 524.184 | S7: 524.12 | T7: 524.077 | U7: 524.305 | V7: 575.068 | W7: 575.125 | X7: 575.285 | Y7: 575.232 | Z7: 575.187 | AA7: 550.181 | AB7: 550.162 | AC7: 550.23 | AD7: 550.711 | AE7: 550.253 | AF7: 525.181 | AG7: 525.118 | AH7: 526.033 | AI7: 525.292 | AJ7: 525.206 | AK7: 600.065 | AL7: 599.944 | AM7: 599.696 | AN7: 600.002 | AO7: 600.411 | AP7: 0.000541831 | AQ7: 0.000205612 | AR7: 0.379682 | AS7: 0.379477 | AT7: 0.000979914 | AU7: 0.000372781 | AV7: 0.380795 | AW7: 0.380422 | AX7: 0.00104938 | AY7: 0.000399227 | AZ7: 0.380841 | BA7: 0.380442 | BB7: 0.000710327 | BC7: 0.000270256 | BD7: 0.380738 | BE7: 0.380467 | BF7: 0.00131415 | BG7: 0.000499458 | BH7: 0.38056 | BI7: 0.380061 | BJ7: 0.000780782 | BK7: 0.0002971 | BL7: 0.380813 | BM7: 0.380516 | BN7: 0.000899097 | BO7: 0.000342191 | BP7: 0.380937 | BQ7: 0.380594 | BR7: 0.000583027 | BS7: 0.000221712 | BT7: 0.380499 | BU7: 0.380277 | BV7: 6.05954e-05 | BW7: 2.30266e-05 | BX7: 0.380029 | BY7: 0.380006 | BZ7: 1.85775e-06 | CA7: 7.05982e-07 | CB7: 0.38002 | CC7: 0.38002 | CD7: -0.000238495 | CE7: -9.06085e-05 | CF7: 0.379828 | CG7: 0.379919 | CH7: 0.000415332 | CI7: 0.000157896 | CJ7: 0.380327 | CK7: 0.380169 | CL7: -6.37156e-05 | CM7: -2.42257e-05 | CN7: 0.380192 | CO7: 0.380216 | CP7: 0.000316947 | CQ7: 0.000120601 | CR7: 0.38063 | CS7: 0.380509 | CT7: 4.84276e-05 | CU7: 1.84368e-05 | CV7: 0.380727 | CW7: 0.380709 | CX7: 8.88546e-05 | CY7: 3.37821e-05 | CZ7: 0.380229 | DA7: 0.380196 | DB7: -0.000546823 | DC7: -0.000207987 | DD7: 0.380147 | DE7: 0.380355 | DF7: 1.75382e-05 | DG7: 6.66861e-06 | DH7: 0.380241 | DI7: 0.380234 | DJ7: -0.000113571 | DK7: -4.3218e-05 | DL7: 0.380494 | DM7: 0.380537 | DN7: 0.000338953 | DO7: 0.000128895 | DP7: 0.380403 | DQ7: 0.380274 | DR7: 0.000696684 | DS7: 0.000264579 | DT7: 0.380033 | DU7: 0.379769 | DV7: 0.000416352 | DW7: 0.000158435 | DX7: 0.380689 | DY7: 0.380531 | DZ7: 0.000794412 | EA7: 0.000301769 | EB7: 0.380166 | EC7: 0.379864 | ED7: 0.000493662 | EE7: 0.000187718 | EF7: 0.380443 | EG7: 0.380256 | EH7: 0.00042087 | EI7: 0.000160109 | EJ7: 0.380585 | EK7: 0.380425 | EL7: -0.000323846 | EM7: -0.000123148 | EN7: 0.380143 | EO7: 0.380266 | EP7: 0.000190557 | EQ7: 7.24237e-05 | ER7: 0.380135 | ES7: 0.380063 | ET7: 0.000299831 | EU7: 0.000113981 | EV7: 0.380265 | EW7: 0.380151 | EX7: 0.000216608 | EY7: 8.25201e-05 | EZ7: 0.381047 | FA7: 0.380965 | FB7: 0.000263599 | FC7: 0.000100285 | FD7: 0.380545 | FE7: 0.380444 | FF7: 0.000172696 | FG7: 6.22692e-05 | FH7: 0.360633 | FI7: 0.360571 | FJ7: -0.000131791 | FK7: -5.01414e-05 | FL7: 0.38041 | FM7: 0.38046 | FN7: -0.000497481 | FO7: -0.000189059 | FP7: 0.379844 | FQ7: 0.380033 | FR7: 5.16502e-05 | FS7: 1.96339e-05 | FT7: 0.380152 | FU7: 0.380133 | FV7: 1.97363e-05 | FW7: 7.51011e-06 | FX7: 0.38053 | FY7: 0.380522 | FZ7: 0.000957279 | GA7: 0.000363442 | GB7: 0.380025 | GC7: 0.379661 | GD7: 0.00117703 | GE7: 0.000447213 | GF7: 0.380398 | GG7: 0.379951 | GH7: 0.0012027 | GI7: 0.000458059 | GJ7: 0.381318 | GK7: 0.38086 | GL7: 0.0011419 | GM7: 0.000434326 | GN7: 0.38079 | GO7: 0.380355 | GP7: 0.0011003 | GQ7: 0.000418067 | GR7: 0.380376 | GS7: 0.379958
A8: 5 | B8: 599.774 | C8: 600.349 | D8: 599.571 | E8: 600.23 | F8: 599.9 | G8: 574.643 | H8: 575.75 | I8: 575.674 | J8: 575.195 | K8: 575.357 | L8: 550.769 | M8: 550.423 | N8: 551.186 | O8: 551.027 | P8: 551.208 | Q8: 525.455 | R8: 525.426 | S8: 525.481 | T8: 525.391 | U8: 525.642 | V8: 575.208 | W8: 575.146 | X8: 575.142 | Y8: 575.192 | Z8: 575.155 | AA8: 550.224 | AB8: 550.303 | AC8: 550.25 | AD8: 550.658 | AE8: 550.167 | AF8: 525.256 | AG8: 525.304 | AH8: 525.988 | AI8: 525.315 | AJ8: 525.24 | AK8: 600.167 | AL8: 599.951 | AM8: 599.719 | AN8: 600.023 | AO8: 600.493 | AP8: 0.000501265 | AQ8: 0.000190218 | AR8: 0.379667 | AS8: 0.379477 | AT8: 0.00113061 | AU8: 0.000430107 | AV8: 0.380852 | AW8: 0.380422 | AX8: 0.00101356 | AY8: 0.000385599 | AZ8: 0.380827 | BA8: 0.380442 | BB8: 0.000750298 | BC8: 0.000285464 | BD8: 0.380753 | BE8: 0.380467 | BF8: 0.00131768 | BG8: 0.000500799 | BH8: 0.380562 | BI8: 0.380061 | BJ8: 0.000523988 | BK8: 0.000199386 | BL8: 0.380716 | BM8: 0.380516 | BN8: 0.000367996 | BO8: 0.000140057 | BP8: 0.380734 | BQ8: 0.380594 | BR8: 0.000602212 | BS8: 0.000229008 | BT8: 0.380506 | BU8: 0.380277 | BV8: -0.000419983 | BW8: -0.000159596 | BX8: 0.379846 | BY8: 0.380006 | BZ8: 6.98073e-05 | CA8: 2.65282e-05 | CB8: 0.380046 | CC8: 0.38002 | CD8: -4.67388e-05 | CE8: -1.77569e-05 | CF8: 0.379901 | CG8: 0.379919 | CH8: 0.000227448 | CI8: 8.64687e-05 | CJ8: 0.380255 | CK8: 0.380169 | CL8: 0.000286617 | CM8: 0.000108976 | CN8: 0.380325 | CO8: 0.380216 | CP8: -1.60572e-05 | CQ8: -6.10993e-06 | CR8: 0.380503 | CS8: 0.380509 | CT8: 0.000478092 | CU8: 0.000182014 | CV8: 0.380891 | CW8: 0.380709 | CX8: 0.000606053 | CY8: 0.000230419 | CZ8: 0.380426 | DA8: 0.380196 | DB8: 0.00016543 | DC8: 6.2922e-05 | DD8: 0.380418 | DE8: 0.380355 | DF8: 0.00035724 | DG8: 0.000135835 | DH8: 0.38037 | DI8: 0.380234 | DJ8: 0.000689064 | DK8: 0.000262215 | DL8: 0.380799 | DM8: 0.380537 | DN8: 0.000486679 | DO8: 0.000185071 | DP8: 0.380459 | DQ8: 0.380274 | DR8: 0.000612458 | DS8: 0.000232592 | DT8: 0.380001 | DU8: 0.379769 | DV8: 0.000106498 | DW8: 4.05258e-05 | DX8: 0.380571 | DY8: 0.380531 | DZ8: 0.000974076 | EA8: 0.000370016 | EB8: 0.380234 | EC8: 0.379864 | ED8: 0.000136838 | EE8: 5.20334e-05 | EF8: 0.380308 | EG8: 0.380256 | EH8: 0.000847665 | EI8: 0.000322473 | EJ8: 0.380747 | EK8: 0.380425 | EL8: -0.000121159 | EM8: -4.60726e-05 | EN8: 0.38022 | EO8: 0.380266 | EP8: 0.000388644 | EQ8: 0.000147709 | ER8: 0.38021 | ES8: 0.380063 | ET8: 5.95556e-05 | EU8: 2.26402e-05 | EV8: 0.380174 | EW8: 0.380151 | EX8: -0.000357719 | EY8: -0.000136278 | EZ8: 0.380828 | FA8: 0.380965 | FB8: 0.000317202 | FC8: 0.000120678 | FD8: 0.380565 | FE8: 0.380444 | FF8: 8.90837e-05 | FG8: 3.2121e-05 | FH8: 0.360603 | FI8: 0.360571 | FJ8: 4.29258e-05 | FK8: 1.63316e-05 | FL8: 0.380477 | FM8: 0.38046 | FN8: -0.000306167 | FO8: -0.000116354 | FP8: 0.379917 | FQ8: 0.380033 | FR8: 0.000307751 | FS8: 0.000116986 | FT8: 0.38025 | FU8: 0.380133 | FV8: 7.36574e-05 | FW8: 2.80283e-05 | FX8: 0.38055 | FY8: 0.380522 | FZ8: 0.000999041 | GA8: 0.000379297 | GB8: 0.380041 | GC8: 0.379661 | GD8: 0.000879715 | GE8: 0.000334249 | GF8: 0.380285 | GG8: 0.379951 | GH8: 0.00120392 | GI8: 0.000458526 | GJ8: 0.381318 | GK8: 0.38086 | GL8: 0.000842466 | GM8: 0.000320436 | GN8: 0.380676 | GO8: 0.380355 | GP8: 0.00137164 | GQ8: 0.000521164 | GR8: 0.380479 | GS8: 0.379958
A9: 6 | B9: 599.881 | C9: 600.32 | D9: 599.576 | E9: 600.169 | F9: 600.119 | G9: 574.939 | H9: 576.072 | I9: 575.764 | J9: 575.256 | K9: 575.482 | L9: 550.91 | M9: 550.717 | N9: 551.278 | O9: 551.168 | P9: 551.34 | Q9: 525.555 | R9: 525.579 | S9: 525.763 | T9: 525.49 | U9: 525.734 | V9: 575.216 | W9: 575.147 | X9: 575.051 | Y9: 575.263 | Z9: 575.165 | AA9: 550.16 | AB9: 550.245 | AC9: 550.121 | AD9: 550.499 | AE9: 550.062 | AF9: 525.166 | AG9: 525.157 | AH9: 525.79 | AI9: 525.068 | AJ9: 525.086 | AK9: 600.201 | AL9: 599.979 | AM9: 599.802 | AN9: 600.044 | AO9: 600.493 | AP9: 0.00127956 | AQ9: 0.000485565 | AR9: 0.379962 | AS9: 0.379477 | AT9: 0.00167672 | AU9: 0.000637862 | AV9: 0.38106 | AW9: 0.380422 | AX9: 0.00131574 | AY9: 0.000500561 | AZ9: 0.380942 | BA9: 0.380442 | BB9: 0.00113005 | BC9: 0.000429949 | BD9: 0.380897 | BE9: 0.380467 | BF9: 0.00175663 | BG9: 0.000667625 | BH9: 0.380729 | BI9: 0.380061 | BJ9: 0.000916073 | BK9: 0.000348581 | BL9: 0.380865 | BM9: 0.380516 | BN9: 0.000402424 | BO9: 0.00015316 | BP9: 0.380748 | BQ9: 0.380594 | BR9: 0.000657743 | BS9: 0.000250125 | BT9: 0.380527 | BU9: 0.380277 | BV9: 1.42534e-05 | BW9: 5.41639e-06 | BX9: 0.380011 | BY9: 0.380006 | BZ9: 0.000362456 | CA9: 0.000137741 | CB9: 0.380158 | CC9: 0.38002 | CD9: 6.31308e-05 | CE9: 2.39845e-05 | CF9: 0.379943 | CG9: 0.379919 | CH9: 0.000128092 | CI9: 4.86964e-05 | CJ9: 0.380218 | CK9: 0.380169 | CL9: -1.91784e-05 | CM9: -7.29194e-06 | CN9: 0.380209 | CO9: 0.380216 | CP9: 0.000250129 | CQ9: 9.51761e-05 | CR9: 0.380604 | CS9: 0.380509 | CT9: 0.000163995 | CU9: 6.24345e-05 | CV9: 0.380771 | CW9: 0.380709 | CX9: 0.000420251 | CY9: 0.000159778 | CZ9: 0.380355 | DA9: 0.380196 | DB9: -0.000307617 | DC9: -0.000117004 | DD9: 0.380238 | DE9: 0.380355 | DF9: 0.000312305 | DG9: 0.000118749 | DH9: 0.380353 | DI9: 0.380234 | DJ9: 0.000182409 | DK9: 6.94134e-05 | DL9: 0.380607 | DM9: 0.380537 | DN9: -0.000147132 | DO9: -5.59505e-05 | DP9: 0.380218 | DQ9: 0.380274 | DR9: 0.000763243 | DS9: 0.000289856 | DT9: 0.380058 | DU9: 0.379769 | DV9: 0.000553191 | DW9: 0.000210506 | DX9: 0.380741 | DY9: 0.380531 | DZ9: 0.00124365 | EA9: 0.000472419 | EB9: 0.380337 | EC9: 0.379864 | ED9: 0.000522921 | EE9: 0.000198844 | EF9: 0.380455 | EG9: 0.380256 | EH9: 0.000798589 | EI9: 0.000303803 | EJ9: 0.380729 | EK9: 0.380425 | EL9: -0.000164652 | EM9: -6.26116e-05 | EN9: 0.380203 | EO9: 0.380266 | EP9: 0.000603927 | EQ9: 0.00022953 | ER9: 0.380292 | ES9: 0.380063 | ET9: 0.000176207 | EU9: 6.69855e-05 | EV9: 0.380218 | EW9: 0.380151 | EX9: -3.64491e-05 | EY9: -1.38858e-05 | EZ9: 0.380951 | FA9: 0.380965 | FB9: 0.000437499 | FC9: 0.000166444 | FD9: 0.380611 | FE9: 0.380444 | FF9: -5.47271e-05 | FG9: -1.9733e-05 | FH9: 0.360551 | FI9: 0.360571 | FJ9: 7.00981e-06 | FK9: 2.66696e-06 | FL9: 0.380463 | FM9: 0.38046 | FN9: -0.000209491 | FO9: -7.96134e-05 | FP9: 0.379954 | FQ9: 0.380033 | FR9: 0.000200842 | FS9: 7.63464e-05 | FT9: 0.380209 | FU9: 0.380133 | FV9: -2.18129e-05 | FW9: -8.30029e-06 | FX9: 0.380514 | FY9: 0.380522 | FZ9: 0.00122368 | GA9: 0.000464585 | GB9: 0.380126 | GC9: 0.379661 | GD9: 0.00175948 | GE9: 0.000668518 | GF9: 0.38062 | GG9: 0.379951 | GH9: 0.00174852 | GI9: 0.000665943 | GJ9: 0.381526 | GK9: 0.38086 | GL9: 0.0018463 | GM9: 0.000702249 | GN9: 0.381058 | GO9: 0.380355 | GP9: 0.00163425 | GQ9: 0.000620949 | GR9: 0.380579 | GS9: 0.379958
A10: 7 | B10: 600.114 | C10: 600.71 | D10: 599.853 | E10: 600.459 | F10: 600.071 | G10: 574.867 | H10: 575.883 | I10: 575.755 | J10: 575.377 | K10: 575.395 | L10: 550.873 | M10: 550.651 | N10: 551.177 | O10: 551.097 | P10: 551.142 | Q10: 525.513 | R10: 525.49 | S10: 525.58 | T10: 525.384 | U10: 525.526 | V10: 575.343 | W10: 575.367 | X10: 575.305 | Y10: 575.32 | Z10: 575.36 | AA10: 550.225 | AB10: 550.408 | AC10: 550.194 | AD10: 550.735 | AE10: 550.201 | AF10: 525.269 | AG10: 525.292 | AH10: 525.897 | AI10: 525.25 | AJ10: 525.178 | AK10: 600.368 | AL10: 600.188 | AM10: 599.953 | AN10: 600.195 | AO10: 600.624 | AP10: 0.00134555 | AQ10: 0.000510606 | AR10: 0.379987 | AS10: 0.379477 | AT10: 0.00157698 | AU10: 0.000599917 | AV10: 0.381022 | AW10: 0.380422 | AX10: 0.00171963 | AY10: 0.00065422 | AZ10: 0.381096 | BA10: 0.380442 | BB10: 0.00119213 | BC10: 0.000453566 | BD10: 0.380921 | BE10: 0.380467 | BF10: 0.00170946 | BG10: 0.000649698 | BH10: 0.380711 | BI10: 0.380061 | BJ10: 0.000919931 | BK10: 0.000350049 | BL10: 0.380866 | BM10: 0.380516 | BN10: 0.000653926 | BO10: 0.000248881 | BP10: 0.380843 | BQ10: 0.380594 | BR10: 0.000459823 | BS10: 0.00017486 | BT10: 0.380452 | BU10: 0.380277 | BV10: -0.00014073 | BW10: -5.34783e-05 | BX10: 0.379953 | BY10: 0.380006 | BZ10: 0.000565069 | CA10: 0.000214737 | CB10: 0.380235 | CC10: 0.38002 | CD10: 0.000114737 | CE10: 4.35908e-05 | CF10: 0.379962 | CG10: 0.379919 | CH10: 2.26072e-05 | CI10: 8.59454e-06 | CJ10: 0.380178 | CK10: 0.380169 | CL10: 0.00034986 | CM10: 0.000133022 | CN10: 0.380349 | CO10: 0.380216 | CP10: 0.000262851 | CQ10: 0.000100017 | CR10: 0.380609 | CS10: 0.380509 | CT10: 0.000303413 | CU10: 0.000115512 | CV10: 0.380824 | CW10: 0.380709 | CX10: 0.000564838 | CY10: 0.000214749 | CZ10: 0.38041 | DA10: 0.380196 | DB10: -0.000282551 | DC10: -0.00010747 | DD10: 0.380247 | DE10: 0.380355 | DF10: 0.000254048 | DG10: 9.65978e-05 | DH10: 0.380331 | DI10: 0.380234 | DJ10: 0.000460057 | DK10: 0.000175069 | DL10: 0.380712 | DM10: 0.380537 | DN10: 0.000337057 | DO10: 0.000128174 | DP10: 0.380403 | DQ10: 0.380274 | DR10: 0.000506244 | DS10: 0.000192256 | DT10: 0.379961 | DU10: 0.379769 | DV10: 0.000358815 | DW10: 0.00013654 | DX10: 0.380667 | DY10: 0.380531 | DZ10: 0.00129394 | EA10: 0.000491521 | EB10: 0.380356 | EC10: 0.379864 | ED10: 0.000556145 | EE10: 0.000211477 | EF10: 0.380467 | EG10: 0.380256 | EH10: 0.000713203 | EI10: 0.00027132 | EJ10: 0.380696 | EK10: 0.380425 | EL10: -0.000120603 | EM10: -4.58612e-05 | EN10: 0.38022 | EO10: 0.380266 | EP10: 7.33122e-05 | EQ10: 2.78632e-05 | ER10: 0.380091 | ES10: 0.380063 | ET10: -0.000111536 | EU10: -4.24006e-05 | EV10: 0.380109 | EW10: 0.380151 | EX10: -0.000312128 | EY10: -0.00011891 | EZ10: 0.380846 | FA10: 0.380965 | FB10: -1.87113e-05 | FC10: -7.11861e-06 | FD10: 0.380437 | FE10: 0.380444 | FF10: -0.000197614 | FG10: -7.12541e-05 | FH10: 0.3605 | FI10: 0.360571 | FJ10: 0.000181265 | FK10: 6.89642e-05 | FL10: 0.380529 | FM10: 0.38046 | FN10: -0.00021899 | FO10: -8.32236e-05 | FP10: 0.37995 | FQ10: 0.380033 | FR10: 0.000139757 | FS10: 5.31264e-05 | FT10: 0.380186 | FU10: 0.380133 | FV10: 9.05143e-05 | FW10: 3.44427e-05 | FX10: 0.380557 | FY10: 0.380522 | FZ10: 0.00125878 | GA10: 0.000477911 | GB10: 0.380139 | GC10: 0.379661 | GD10: 0.00151284 | GE10: 0.000574806 | GF10: 0.380526 | GG10: 0.379951 | GH10: 0.00170969 | GI10: 0.000651153 | GJ10: 0.381511 | GK10: 0.38086 | GL10: 0.00168777 | GM10: 0.000641954 | GN10: 0.380997 | GO10: 0.380355 | GP10: 0.00162255 | GQ10: 0.000616503 | GR10: 0.380575 | GS10: 0.379958
A11: 8 | B11: 600.392 | C11: 600.889 | D11: 600.008 | E11: 600.622 | F11: 600.314 | G11: 575.09 | H11: 576.104 | I11: 575.884 | J11: 575.474 | K11: 575.608 | L11: 551.048 | M11: 550.853 | N11: 551.381 | O11: 551.295 | P11: 551.444 | Q11: 525.701 | R11: 525.665 | S11: 525.747 | T11: 525.603 | U11: 525.823 | V11: 575.584 | W11: 575.687 | X11: 575.626 | Y11: 575.759 | Z11: 575.776 | AA11: 550.666 | AB11: 550.81 | AC11: 550.582 | AD11: 551.149 | AE11: 550.8 | AF11: 525.794 | AG11: 525.816 | AH11: 526.505 | AI11: 525.795 | AJ11: 525.707 | AK11: 600.528 | AL11: 600.441 | AM11: 600.174 | AN11: 600.439 | AO11: 600.723 | AP11: 0.0014701 | AQ11: 0.00055787 | AR11: 0.380035 | AS11: 0.379477 | AT11: 0.00197537 | AU11: 0.000751473 | AV11: 0.381173 | AW11: 0.380422 | AX11: 0.00213446 | AY11: 0.000812037 | AZ11: 0.381254 | BA11: 0.380442 | BB11: 0.00127486 | BC11: 0.000485042 | BD11: 0.380952 | BE11: 0.380467 | BF11: 0.00217104 | BG11: 0.000825127 | BH11: 0.380886 | BI11: 0.380061 | BJ11: 0.00114196 | BK11: 0.000434533 | BL11: 0.380951 | BM11: 0.380516 | BN11: 0.000544174 | BO11: 0.00020711 | BP11: 0.380802 | BQ11: 0.380594 | BR11: 0.00077703 | BS11: 0.000295487 | BT11: 0.380573 | BU11: 0.380277 | BV11: 0.000398529 | BW11: 0.000151443 | BX11: 0.380158 | BY11: 0.380006 | BZ11: 0.00013873 | CA11: 5.27203e-05 | CB11: 0.380073 | CC11: 0.38002 | CD11: 0.000309452 | CE11: 0.000117567 | CF11: 0.380036 | CG11: 0.379919 | CH11: 0.000368374 | CI11: 0.000140045 | CJ11: 0.380309 | CK11: 0.380169 | CL11: 0.00014857 | CM11: 5.64886e-05 | CN11: 0.380273 | CO11: 0.380216 | CP11: 0.000330626 | CQ11: 0.000125806 | CR11: 0.380635 | CS11: 0.380509 | CT11: 0.000817956 | CU11: 0.000311403 | CV11: 0.38102 | CW11: 0.380709 | CX11: 0.00101344 | CY11: 0.000385304 | CZ11: 0.380581 | DA11: 0.380196 | DB11: 9.19512e-05 | DC11: 3.49741e-05 | DD11: 0.38039 | DE11: 0.380355 | DF11: 0.000528338 | DG11: 0.000200892 | DH11: 0.380435 | DI11: 0.380234 | DJ11: 0.000849794 | DK11: 0.000323378 | DL11: 0.380861 | DM11: 0.380537 | DN11: 0.000369734 | DO11: 0.0001406 | DP11: 0.380415 | DQ11: 0.380274 | DR11: 0.000801307 | DS11: 0.000304311 | DT11: 0.380073 | DU11: 0.379769 | DV11: 0.000878256 | DW11: 0.000334204 | DX11: 0.380865 | DY11: 0.380531 | DZ11: 0.00104104 | EA11: 0.000395453 | EB11: 0.38026 | EC11: 0.379864 | ED11: 0.000259309 | EE11: 9.86038e-05 | EF11: 0.380354 | EG11: 0.380256 | EH11: 0.000939904 | EI11: 0.000357563 | EJ11: 0.380783 | EK11: 0.380425 | EL11: -5.40583e-06 | EM11: -2.05565e-06 | EN11: 0.380264 | EO11: 0.380266 | EP11: 0.000634056 | EQ11: 0.000240981 | ER11: 0.380304 | ES11: 0.380063 | ET11: 0.000247258 | EU11: 9.39955e-05 | EV11: 0.380245 | EW11: 0.380151 | EX11: 7.04513e-05 | EY11: 2.68394e-05 | EZ11: 0.380991 | FA11: 0.380965 | FB11: 0.000698605 | FC11: 0.00026578 | FD11: 0.38071 | FE11: 0.380444 | FF11: 0.000176844 | FG11: 6.37648e-05 | FH11: 0.360635 | FI11: 0.360571 | FJ11: 2.39386e-05 | FK11: 9.10767e-06 | FL11: 0.38047 | FM11: 0.38046 | FN11: -0.000194467 | FO11: -7.3904e-05 | FP11: 0.379959 | FQ11: 0.380033 | FR11: 0.000557625 | FS11: 0.000211971 | FT11: 0.380345 | FU11: 0.380133 | FV11: 0.000207493 | FW11: 7.89556e-05 | FX11: 0.380601 | FY11: 0.380522 | FZ11: 0.00156915 | GA11: 0.000595746 | GB11: 0.380257 | GC11: 0.379661 | GD11: 0.0012855 | GE11: 0.000488427 | GF11: 0.380439 | GG11: 0.379951 | GH11: 0.00174969 | GI11: 0.000666388 | GJ11: 0.381526 | GK11: 0.38086 | GL11: 0.00192545 | GM11: 0.000732355 | GN11: 0.381088 | GO11: 0.380355 | GP11: 0.00193705 | GQ11: 0.000735998 | GR11: 0.380694 | GS11: 0.379958
A12: 9 | B12: 600.395 | C12: 600.856 | D12: 600.445 | E12: 600.667 | F12: 600.459 | G12: 575.284 | H12: 576.32 | I12: 576.208 | J12: 575.651 | K12: 575.97 | L12: 551.323 | M12: 551.094 | N12: 551.765 | O12: 551.705 | P12: 551.723 | Q12: 526.001 | R12: 526.026 | S12: 526.033 | T12: 525.879 | U12: 526.193 | V12: 575.518 | W12: 575.397 | X12: 575.47 | Y12: 575.563 | Z12: 575.551 | AA12: 550.451 | AB12: 550.502 | AC12: 550.38 | AD12: 550.859 | AE12: 550.438 | AF12: 525.527 | AG12: 525.513 | AH12: 526.347 | AI12: 525.413 | AJ12: 525.433 | AK12: 600.524 | AL12: 600.278 | AM12: 600.102 | AN12: 600.409 | AO12: 600.902 | AP12: 0.00152093 | AQ12: 0.000577156 | AR12: 0.380054 | AS12: 0.379477 | AT12: 0.00200999 | AU12: 0.000764642 | AV12: 0.381187 | AW12: 0.380422 | AX12: 0.00200148 | AY12: 0.000761446 | AZ12: 0.381203 | BA12: 0.380442 | BB12: 0.00131329 | BC12: 0.000499666 | BD12: 0.380967 | BE12: 0.380467 | BF12: 0.00237278 | BG12: 0.000901799 | BH12: 0.380963 | BI12: 0.380061 | BJ12: 0.000902715 | BK12: 0.000343498 | BL12: 0.38086 | BM12: 0.380516 | BN12: 0.000370587 | BO12: 0.000141044 | BP12: 0.380735 | BQ12: 0.380594 | BR12: 0.000663305 | BS12: 0.00025224 | BT12: 0.380529 | BU12: 0.380277 | BV12: 4.99757e-05 | BW12: 1.89911e-05 | BX12: 0.380025 | BY12: 0.380006 | BZ12: 0.000180992 | CA12: 6.87806e-05 | CB12: 0.380089 | CC12: 0.38002 | CD12: 0.000465978 | CE12: 0.000177034 | CF12: 0.380096 | CG12: 0.379919 | CH12: 0.00037394 | CI12: 0.00014216 | CJ12: 0.380311 | CK12: 0.380169 | CL12: 0.000409069 | CM12: 0.000155535 | CN12: 0.380372 | CO12: 0.380216 | CP12: -0.000182175 | CQ12: -6.93192e-05 | CR12: 0.38044 | CS12: 0.380509 | CT12: 0.000577622 | CU12: 0.000219906 | CV12: 0.380929 | CW12: 0.380709 | CX12: 0.00104984 | CY12: 0.000399143 | CZ12: 0.380595 | DA12: 0.380196 | DB12: 9.76099e-07 | DC12: 3.71264e-07 | DD12: 0.380355 | DE12: 0.380355 | DF12: 0.000535366 | DG12: 0.000203564 | DH12: 0.380438 | DI12: 0.380234 | DJ12: 0.000560456 | DK12: 0.000213275 | DL12: 0.38075 | DM12: 0.380537 | DN12: 0.000241391 | DO12: 9.17948e-05 | DP12: 0.380366 | DQ12: 0.380274 | DR12: 0.000476503 | DS12: 0.000180961 | DT12: 0.37995 | DU12: 0.379769 | DV12: 0.000557518 | DW12: 0.000212153 | DX12: 0.380743 | DY12: 0.380531 | DZ12: 0.000655626 | EA12: 0.000249049 | EB12: 0.380113 | EC12: 0.379864 | ED12: 0.000410365 | EE12: 0.000156043 | EF12: 0.380412 | EG12: 0.380256 | EH12: 0.00085531 | EI12: 0.000325381 | EJ12: 0.38075 | EK12: 0.380425 | EL12: -5.06336e-05 | EM12: -1.92542e-05 | EN12: 0.380246 | EO12: 0.380266 | EP12: 0.000205464 | EQ12: 7.80892e-05 | ER12: 0.380141 | ES12: 0.380063 | ET12: 1.6734e-06 | EU12: 6.36145e-07 | EV12: 0.380152 | EW12: 0.380151 | EX12: -0.000300885 | EY12: -0.000114626 | EZ12: 0.38085 | FA12: 0.380965 | FB12: 0.000309565 | FC12: 0.000117772 | FD12: 0.380562 | FE12: 0.380444 | FF12: 0.000413606 | FG12: 0.000149134 | FH12: 0.36072 | FI12: 0.360571 | FJ12: 8.80642e-05 | FK12: 3.35049e-05 | FL12: 0.380494 | FM12: 0.38046 | FN12: 1.70381e-05 | FO12: 6.47506e-06 | FP12: 0.38004 | FQ12: 0.380033 | FR12: 0.00019515 | FS12: 7.41831e-05 | FT12: 0.380207 | FU12: 0.380133 | FV12: -1.29777e-05 | FW12: -4.93831e-06 | FX12: 0.380517 | FY12: 0.380522 | FZ12: 0.00157408 | GA12: 0.000597616 | GB12: 0.380259 | GC12: 0.379661 | GD12: 0.00155255 | GE12: 0.000589895 | GF12: 0.380541 | GG12: 0.379951 | GH12: 0.00208432 | GI12: 0.000793835 | GJ12: 0.381654 | GK12: 0.38086 | GL12: 0.00209828 | GM12: 0.000798092 | GN12: 0.381154 | GO12: 0.380355 | GP12: 0.00227465 | GQ12: 0.000864274 | GR12: 0.380823 | GS12: 0.379958
A13: 10 | B13: 600.345 | C13: 600.718 | D13: 599.913 | E13: 600.397 | F13: 600.261 | G13: 575.104 | H13: 576.173 | I13: 575.986 | J13: 575.605 | K13: 575.736 | L13: 551.168 | M13: 550.917 | N13: 551.469 | O13: 551.324 | P13: 551.474 | Q13: 525.826 | R13: 525.8 | S13: 525.901 | T13: 525.678 | U13: 525.899 | V13: 575.454 | W13: 575.42 | X13: 575.361 | Y13: 575.488 | Z13: 575.491 | AA13: 550.409 | AB13: 550.443 | AC13: 550.301 | AD13: 550.849 | AE13: 550.303 | AF13: 525.522 | AG13: 525.519 | AH13: 526.174 | AI13: 525.439 | AJ13: 525.397 | AK13: 600.425 | AL13: 600.354 | AM13: 600.098 | AN13: 600.27 | AO13: 600.625 | AP13: 0.00196083 | AQ13: 0.000744091 | AR13: 0.380221 | AS13: 0.379477 | AT13: 0.00219601 | AU13: 0.000835412 | AV13: 0.381257 | AW13: 0.380422 | AX13: 0.0020394 | AY13: 0.000775872 | AZ13: 0.381217 | BA13: 0.380442 | BB13: 0.00196729 | BC13: 0.000748491 | BD13: 0.381216 | BE13: 0.380467 | BF13: 0.00302447 | BG13: 0.00114948 | BH13: 0.381211 | BI13: 0.380061 | BJ13: 0.000786862 | BK13: 0.000299414 | BL13: 0.380816 | BM13: 0.380516 | BN13: 0.000599092 | BO13: 0.000228011 | BP13: 0.380822 | BQ13: 0.380594 | BR13: 0.000735372 | BS13: 0.000279645 | BT13: 0.380557 | BU13: 0.380277 | BV13: 0.000230939 | BW13: 8.77583e-05 | BX13: 0.380094 | BY13: 0.380006 | BZ13: 0.000618464 | CA13: 0.000235029 | CB13: 0.380255 | CC13: 0.38002 | CD13: 0.000483315 | CE13: 0.00018362 | CF13: 0.380102 | CG13: 0.379919 | CH13: 0.000455103 | CI13: 0.000173016 | CJ13: 0.380342 | CK13: 0.380169 | CL13: 6.72139e-05 | CM13: 2.55558e-05 | CN13: 0.380242 | CO13: 0.380216 | CP13: 7.43939e-05 | CQ13: 2.83075e-05 | CR13: 0.380537 | CS13: 0.380509 | CT13: 0.000228172 | CU13: 8.68672e-05 | CV13: 0.380796 | CW13: 0.380709 | CX13: 0.000665662 | CY13: 0.000253082 | CZ13: 0.380449 | DA13: 0.380196 | DB13: -0.000250914 | DC13: -9.54364e-05 | DD13: 0.380259 | DE13: 0.380355 | DF13: 0.00062029 | DG13: 0.000235856 | DH13: 0.38047 | DI13: 0.380234 | DJ13: 0.00043379 | DK13: 0.000165073 | DL13: 0.380702 | DM13: 0.380537 | DN13: -5.47934e-05 | DO13: -2.08365e-05 | DP13: 0.380254 | DQ13: 0.380274 | DR13: 0.000621477 | DS13: 0.000236018 | DT13: 0.380005 | DU13: 0.379769 | DV13: 0.00108333 | DW13: 0.000412242 | DX13: 0.380943 | DY13: 0.380531 | DZ13: 0.00123587 | EA13: 0.000469464 | EB13: 0.380334 | EC13: 0.379864 | ED13: 0.000488481 | EE13: 0.000185748 | EF13: 0.380441 | EG13: 0.380256 | EH13: 0.00113706 | EI13: 0.000432565 | EJ13: 0.380858 | EK13: 0.380425 | EL13: 0.000207679 | EM13: 7.89731e-05 | EN13: 0.380345 | EO13: 0.380266 | EP13: 0.000518405 | EQ13: 0.000197026 | ER13: 0.38026 | ES13: 0.380063 | ET13: -1.5388e-05 | EU13: -5.84978e-06 | EV13: 0.380146 | EW13: 0.380151 | EX13: -0.000241706 | EY13: -9.20816e-05 | EZ13: 0.380872 | FA13: 0.380965 | FB13: 0.000666618 | FC13: 0.000253611 | FD13: 0.380698 | FE13: 0.380444 | FF13: 0.000414831 | FG13: 0.000149576 | FH13: 0.360721 | FI13: 0.360571 | FJ13: 7.99213e-05 | FK13: 3.04069e-05 | FL13: 0.380491 | FM13: 0.38046 | FN13: 0.000356611 | FO13: 0.000135524 | FP13: 0.380169 | FQ13: 0.380033 | FR13: 0.000221474 | FS13: 8.41896e-05 | FT13: 0.380217 | FU13: 0.380133 | FV13: 0.00021918 | FW13: 8.3403e-05 | FX13: 0.380606 | FY13: 0.380522 | FZ13: 0.00184131 | GA13: 0.000699074 | GB13: 0.38036 | GC13: 0.379661 | GD13: 0.0019417 | GE13: 0.000737752 | GF13: 0.380689 | GG13: 0.379951 | GH13: 0.00236425 | GI13: 0.000900448 | GJ13: 0.38176 | GK13: 0.38086 | GL13: 0.00242138 | GM13: 0.000920984 | GN13: 0.381276 | GO13: 0.380355 | GP13: 0.0026168 | GQ13: 0.000994276 | GR13: 0.380953 | GS13: 0.379958
A14: 11 | B14: 600.637 | C14: 600.966 | D14: 600.217 | E14: 600.548 | F14: 600.691 | G14: 575.617 | H14: 576.77 | I14: 576.506 | J14: 575.992 | K14: 576.281 | L14: 551.918 | M14: 551.636 | N14: 552.264 | O14: 552.064 | P14: 552.232 | Q14: 526.698 | R14: 526.734 | S14: 526.713 | T14: 526.539 | U14: 526.73 | V14: 575.381 | W14: 575.553 | X14: 575.449 | Y14: 575.606 | Z14: 575.625 | AA14: 550.485 | AB14: 550.543 | AC14: 550.613 | AD14: 550.974 | AE14: 550.48 | AF14: 525.675 | AG14: 525.629 | AH14: 526.323 | AI14: 525.609 | AJ14: 525.73 | AK14: 600.643 | AL14: 600.408 | AM14: 600.222 | AN14: 600.447 | AO14: 600.899 | AP14: 0.00221438 | AQ14: 0.000840305 | AR14: 0.380317 | AS14: 0.379477 | AT14: 0.00239452 | AU14: 0.000910929 | AV14: 0.381333 | AW14: 0.380422 | AX14: 0.00275585 | AY14: 0.00104844 | AZ14: 0.38149 | BA14: 0.380442 | BB14: 0.00210327 | BC14: 0.000800227 | BD14: 0.381268 | BE14: 0.380467 | BF14: 0.00281372 | BG14: 0.00106939 | BH14: 0.38113 | BI14: 0.380061 | BJ14: 0.00118503 | BK14: 0.000450925 | BL14: 0.380967 | BM14: 0.380516 | BN14: 0.000653241 | BO14: 0.00024862 | BP14: 0.380843 | BQ14: 0.380594 | BR14: 0.000599469 | BS14: 0.000227965 | BT14: 0.380505 | BU14: 0.380277 | BV14: 0.000203833 | BW14: 7.74577e-05 | BX14: 0.380084 | BY14: 0.380006 | BZ14: 0.000516653 | CA14: 0.000196338 | CB14: 0.380216 | CC14: 0.38002 | CD14: 0.000172981 | CE14: 6.57188e-05 | CF14: 0.379984 | CG14: 0.379919 | CH14: 0.000478929 | CI14: 0.000182074 | CJ14: 0.380351 | CK14: 0.380169 | CL14: 0.00076248 | CM14: 0.000289907 | CN14: 0.380506 | CO14: 0.380216 | CP14: 0.000128652 | CQ14: 4.89531e-05 | CR14: 0.380558 | CS14: 0.380509 | CT14: 0.000536801 | CU14: 0.000204365 | CV14: 0.380913 | CW14: 0.380709 | CX14: 0.000649644 | CY14: 0.000246992 | CZ14: 0.380443 | DA14: 0.380196 | DB14: -4.84223e-05 | DC14: -1.84177e-05 | DD14: 0.380336 | DE14: 0.380355 | DF14: 0.000195969 | DG14: 7.45142e-05 | DH14: 0.380309 | DI14: 0.380234 | DJ14: 0.000637605 | DK14: 0.000242632 | DL14: 0.38078 | DM14: 0.380537 | DN14: 0.000239298 | DO14: 9.09991e-05 | DP14: 0.380365 | DQ14: 0.380274 | DR14: 0.000817782 | DS14: 0.000310568 | DT14: 0.380079 | DU14: 0.379769 | DV14: 0.000937982 | DW14: 0.000356931 | DX14: 0.380888 | DY14: 0.380531 | DZ14: 0.00112126 | EA14: 0.000425926 | EB14: 0.38029 | EC14: 0.379864 | ED14: 0.000862327 | EE14: 0.000327905 | EF14: 0.380584 | EG14: 0.380256 | EH14: 0.000867389 | EI14: 0.000329977 | EJ14: 0.380755 | EK14: 0.380425 | EL14: 0.000210182 | EM14: 7.9925e-05 | EN14: 0.380346 | EO14: 0.380266 | EP14: 0.000372507 | EQ14: 0.000141576 | ER14: 0.380204 | ES14: 0.380063 | ET14: 0.000353325 | EU14: 0.000134317 | EV14: 0.380286 | EW14: 0.380151 | EX14: 7.42179e-05 | EY14: 2.82744e-05 | EZ14: 0.380993 | FA14: 0.380965 | FB14: 0.000866155 | FC14: 0.000329524 | FD14: 0.380774 | FE14: 0.380444 | FF14: 0.000245369 | FG14: 8.84729e-05 | FH14: 0.36066 | FI14: 0.360571 | FJ14: 0.000290738 | FK14: 0.000110614 | FL14: 0.380571 | FM14: 0.38046 | FN14: -0.000147698 | FO14: -5.61301e-05 | FP14: 0.379977 | FQ14: 0.380033 | FR14: 0.000381377 | FS14: 0.000144974 | FT14: 0.380278 | FU14: 0.380133 | FV14: 3.79182e-05 | FW14: 1.44287e-05 | FX14: 0.380537 | FY14: 0.380522 | FZ14: 0.00206652 | GA14: 0.000784576 | GB14: 0.380446 | GC14: 0.379661 | GD14: 0.00214535 | GE14: 0.000815127 | GF14: 0.380766 | GG14: 0.379951 | GH14: 0.00240077 | GI14: 0.000914359 | GJ14: 0.381774 | GK14: 0.38086 | GL14: 0.00243948 | GM14: 0.000927871 | GN14: 0.381283 | GO14: 0.380355 | GP14: 0.00267521 | GQ14: 0.00101647 | GR14: 0.380975 | GS14: 0.379958
... A474: 471 | B474: 601.08 | C474: 601.552 | D474: 601.05 | E474: 601.309 | F474: 600.114 | G474: 575.516 | H474: 576.419 | I474: 576.509 | J474: 576.146 | K474: 576.442 | L474: 551.976 | M474: 551.806 | N474: 552.658 | O474: 552.476 | P474: 552.626 | Q474: 526.917 | R474: 527.143 | S474: 527.016 | T474: 526.869 | U474: 527.23 | V474: 569.461 | W474: 569.21 | X474: 569.64 | Y474: 569.238 | Z474: 569.618 | AA474: 542.948 | AB474: 542.782 | AC474: 542.742 | AD474: 543.216 | AE474: 543.188 | AF474: 517.246 | AG474: 516.907 | AH474: 517.527 | AI474: 517.076 | AJ474: 517.51 | AK474: 599.475 | AL474: 599.782 | AM474: 599.285 | AN474: 599.992 | AO474: 599.885 | AP474: 0.0962285 | AQ474: 0.0365165 | AR474: 0.415993 | AS474: 0.379477 | AT474: 0.0941602 | AU474: 0.0358206 | AV474: 0.416243 | AW474: 0.380422 | AX474: 0.0965417 | AY474: 0.0367285 | AZ474: 0.41717 | BA474: 0.380442 | BB474: 0.0936875 | BC474: 0.035645 | BD474: 0.416112 | BE474: 0.380467 | BF474: 0.0990356 | BG474: 0.0376396 | BH474: 0.417701 | BI474: 0.380061 | BJ474: 0.0179873 | BK474: 0.00684446 | BL474: 0.387361 | BM474: 0.380516 | BN474: 0.016795 | BO474: 0.00639208 | BP474: 0.386986 | BQ474: 0.380594 | BR474: 0.017356 | BS474: 0.00660007 | BT474: 0.386877 | BU474: 0.380277 | BV474: 0.0174192 | BW474: 0.00661939 | BX474: 0.386625 | BY474: 0.380006 | BZ474: 0.0190117 | CA474: 0.00722481 | CB474: 0.387245 | CC474: 0.38002 | CD474: 0.00519535 | CE474: 0.00197381 | CF474: 0.381892 | CG474: 0.379919 | CH474: 0.00491087 | CI474: 0.00186696 | CJ474: 0.382036 | CK474: 0.380169 | CL474: 0.00514763 | CM474: 0.00195721 | CN474: 0.382173 | CO474: 0.380216 | CP474: 0.00584891 | CQ474: 0.00222556 | CR474: 0.382735 | CS474: 0.380509 | CT474: 0.00661897 | CU474: 0.0025199 | CV474: 0.383229 | CW474: 0.380709 | CX474: 0.00241797 | CY474: 0.000919302 | CZ474: 0.381115 | DA474: 0.380196 | DB474: 9.57127e-05 | DC474: 3.64048e-05 | DD474: 0.380391 | DE474: 0.380355 | DF474: 0.00256057 | DG474: 0.000973617 | DH474: 0.381208 | DI474: 0.380234 | DJ474: 0.00250751 | DK474: 0.000954201 | DL474: 0.381491 | DM474: 0.380537 | DN474: 0.00123095 | DO474: 0.0004681 | DP474: 0.380743 | DQ474: 0.380274 | DR474: 0.0159338 | DS474: 0.00605115 | DT474: 0.38582 | DU474: 0.379769 | DV474: 0.0147835 | DW474: 0.00562557 | DX474: 0.386156 | DY474: 0.380531 | DZ474: 0.015487 | EA474: 0.00588294 | EB474: 0.385747 | EC474: 0.379864 | ED474: 0.0161824 | EE474: 0.00615345 | EF474: 0.386409 | EG474: 0.380256 | EH474: 0.0160355 | EI474: 0.00610029 | EJ474: 0.386525 | EK474: 0.380425 | EL474: 0.00438145 | EM474: 0.00166611 | EN474: 0.381932 | EO474: 0.380266 | EP474: 0.00521639 | EQ474: 0.00198256 | ER474: 0.382045 | ES474: 0.380063 | ET474: 0.00446764 | EU474: 0.00169838 | EV474: 0.38185 | EW474: 0.380151 | EX474: 0.00453582 | EY474: 0.00172799 | EZ474: 0.382693 | FA474: 0.380965 | FB474: 0.00513561 | FC474: 0.00195381 | FD474: 0.382398 | FE474: 0.380444 | FF474: 0.0012791 | FG474: 0.000461207 | FH474: 0.361032 | FI474: 0.360571 | FJ474: 0.00127384 | FK474: 0.000484645 | FL474: 0.380945 | FM474: 0.38046 | FN474: 0.00130819 | FO474: 0.000497156 | FP474: 0.380531 | FQ474: 0.380033 | FR474: 0.00185112 | FS474: 0.00070367 | FT474: 0.380836 | FU474: 0.380133 | FV474: 0.00194557 | FW474: 0.000740334 | FX474: 0.381263 | FY474: 0.380522 | FZ474: 0.0920565 | GA474: 0.0349503 | GB474: 0.414612 | GC474: 0.379661 | GD474: 0.0900806 | GE474: 0.0342262 | GF474: 0.414177 | GG474: 0.379951 | GH474: 0.0904783 | GI474: 0.0344596 | GJ474: 0.415319 | GK474: 0.38086 | GL474: 0.0910298 | GM474: 0.0346237 | GN474: 0.414979 | GO474: 0.380355 | GP474: 0.0949748 | GQ474: 0.0360865 | GR474: 0.416045 | GS474: 0.379958

Sheet ΔT 600
A1: =MAX(B2:B474)-MIN(B2:B474) | B1: =MAX(C2:C474)-MIN(C2:C474) | C1: =MAX(D2:D474)-MIN(D2:D474) | D1: =MAX(E2:E474)-MIN(E2:E474) | E1: =MAX(F2:F474)-MIN(F2:F474) | F1: P4 | G1: E0 - 600 | K1: E1 - 600 | O1: E2 - 600 | S1: E3 - 600 | W1: E4 - 600 | AB1: P35 - 600 | AC1: P36 - 600 | AD1: P37 - 600 | AE1: P38 - 600 | AF1: P39 - 600 | AG1: E35 - 600 | AK1: E36 - 600 | AO1: E37 - 600 | AS1: E38 - 600 | AW1: E39 - 600
A2: Index [1] | B2: Temperature [C] | C2: Temperature [C] | D2: Temperature [C] | E2: Temperature [C] | F2: Temperature [C] | G2: ΔL/L0 [1] | H2: ΔL [mm] | I2: L1 [mm] | J2: L0 [mm] | K2: ΔL/L0 [1] | L2: ΔL [mm] | M2: L1 [mm] | N2: L0 [mm] | O2: ΔL/L0 [1] | P2: ΔL [mm] | Q2: L1 [mm] | R2: L0 [mm] | S2: ΔL/L0 [1] | T2: ΔL [mm] | U2: L1 [mm] | V2: L0 [mm] | W2: ΔL/L0 [1] | X2: ΔL [mm] | Y2: L1 [mm] | Z2: L0 [mm] | AB2: Temperature [C] | AC2: Temperature [C] | AD2: Temperature [C] | AE2: Temperature [C] | AF2: Temperature [C] | AG2: ΔL/L0 [1] | AH2: ΔL [mm] | AI2: L1 [mm] | AJ2: L0 [mm] | AK2: ΔL/L0 [1] | AL2: ΔL [mm] | AM2: L1 [mm] | AN2: L0 [mm] | AO2: ΔL/L0 [1] | AP2: ΔL [mm] | AQ2: L1 [mm] | AR2: L0 [mm] | AS2: ΔL/L0 [1] | AT2: ΔL [mm] | AU2: L1 [mm] | AV2: L0 [mm] | AW2: ΔL/L0 [1] | AX2: ΔL [mm] | AY2: L1 [mm] | AZ2: L0 [mm]
A3: 0 | B3: 599.855 | C3: 600.18 | D3: 599.458 | E3: 599.921 | F3: 599.732 | G3: 0 | H3: 0 | I3: 0.379477 | J3: 0.379477 | K3: 0 | L3: 0 | M3: 0.380422 | N3: 0.380422 | O3: 0 | P3: 0 | Q3: 0.380442 | R3: 0.380442 | S3: 0 | T3: 0 | U3: 0.380467 | V3: 0.380467 | W3: 0 | X3: 0 | Y3: 0.380061 | Z3: 0.380061 | AB3: 600.011 | AC3: 599.875 | AD3: 599.68 | AE3: 599.796 | AF3: 600.163 | AG3: 0 | AH3: 0 | AI3: 0.379661 | AJ3: 0.379661 | AK3: 0 | AL3: 0 | AM3: 0.379951 | AN3: 0.379951 | AO3: 0 | AP3: 0 | AQ3: 0.38086 | AR3: 0.38086 | AS3: 0 | AT3: 0 | AU3: 0.380355 | AV3: 0.380355 | AW3: 0 | AX3: 0 | AY3: 0.379958 | AZ3: 0.379958
A4: 1 | B4: 599.94 | C4: 600.374 | D4: 599.537 | E4: 600.045 | F4: 599.891 | G4: -9.8174e-06 | H4: -3.72547e-06 | I4: 0.379473 | J4: 0.379477 | K4: 0.000491383 | L4: 0.000186933 | M4: 0.380609 | N4: 0.380422 | O4: 0.000760679 | P4: 0.000289394 | Q4: 0.380731 | R4: 0.380442 | S4: -0.000120421 | T4: -4.58162e-05 | U4: 0.380422 | V4: 0.380467 | W4: 0.000377364 | X4: 0.000143421 | Y4: 0.380204 | Z4: 0.380061 | AB4: 600.143 | AC4: 599.842 | AD4: 599.634 | AE4: 599.896 | AF4: 600.271 | AG4: 9.2086e-05 | AH4: 3.49615e-05 | AI4: 0.379696 | AJ4: 0.379661 | AK4: -0.000121672 | AL4: -4.62292e-05 | AM4: 0.379905 | AN4: 0.379951 | AO4: 8.97826e-05 | AP4: 3.41946e-05 | AQ4: 0.380894 | AR4: 0.38086 | AS4: -8.43401e-05 | AT4: -3.20792e-05 | AU4: 0.380323 | AV4: 0.380355 | AW4: 3.44271e-05 | AX4: 1.30809e-05 | AY4: 0.379971 | AZ4: 0.379958
A5: 2 | B5: 599.906 | C5: 600.524 | D5: 600.167 | E5: 600.319 | F5: 600.169 | G5: 0.000117935 | H5: 4.47536e-05 | I5: 0.379521 | J5: 0.379477 | K5: 0.000527873 | L5: 0.000200814 | M5: 0.380623 | N5: 0.380422 | O5: 0.000657871 | P5: 0.000250281 | Q5: 0.380692 | R5: 0.380442 | S5: 0.000142197 | T5: 5.41013e-05 | U5: 0.380521 | V5: 0.380467 | W5: 0.000668719 | X5: 0.000254154 | Y5: 0.380315 | Z5: 0.380061 | AB5: 600.311 | AC5: 600.116 | AD5: 600.06 | AE5: 600.3 | AF5: 600.597 | AG5: 0.000231738 | AH5: 8.79819e-05 | AI5: 0.379749 | AJ5: 0.379661 | AK5: 0.000492284 | AL5: 0.000187044 | AM5: 0.380138 | AN5: 0.379951 | AO5: 0.000700582 | AP5: 0.000266823 | AQ5: 0.381127 | AR5: 0.38086 | AS5: 0.000795344 | AT5: 0.000302514 | AU5: 0.380658 | AV5: 0.380355 | AW5: 0.000626149 | AX5: 0.00023791 | AY5: 0.380196 | AZ5: 0.379958
A6: 3 | B6: 599.861 | C6: 600.441 | D6: 600.03 | E6: 600.206 | F6: 600.062 | G6: 0.00031252 | H6: 0.000118594 | I6: 0.379595 | J6: 0.379477 | K6: 0.000521143 | L6: 0.000198254 | M6: 0.38062 | N6: 0.380422 | O6: 0.00074411 | P6: 0.000283091 | Q6: 0.380725 | R6: 0.380442 | S6: 0.000538677 | T6: 0.000204949 | U6: 0.380672 | V6: 0.380467 | W6: 0.00120336 | X6: 0.000457348 | Y6: 0.380518 | Z6: 0.380061 | AB6: 600.05 | AC6: 599.821 | AD6: 599.734 | AE6: 600.042 | AF6: 600.378 | AG6: 0.000417287 | AH6: 0.000158428 | AI6: 0.37982 | AJ6: 0.379661 | AK6: 0.000619256 | AL6: 0.000235287 | AM6: 0.380186 | AN6: 0.379951 | AO6: 0.00072572 | AP6: 0.000276397 | AQ6: 0.381136 | AR6: 0.38086 | AS6: 0.000868747 | AT6: 0.000330433 | AU6: 0.380686 | AV6: 0.380355 | AW6: 0.00076269 | AX6: 0.000289791 | AY6: 0.380248 | AZ6: 0.379958
A7: 4 | B7: 599.702 | C7: 600.267 | D7: 599.867 | E7: 599.891 | F7: 599.785 | G7: 0.000541831 | H7: 0.000205612 | I7: 0.379682 | J7: 0.379477 | K7: 0.000979914 | L7: 0.000372781 | M7: 0.380795 | N7: 0.380422 | O7: 0.00104938 | P7: 0.000399227 | Q7: 0.380841 | R7: 0.380442 | S7: 0.000710327 | T7: 0.000270256 | U7: 0.380738 | V7: 0.380467 | W7: 0.00131415 | X7: 0.000499458 | Y7: 0.38056 | Z7: 0.380061 | AB7: 600.065 | AC7: 599.944 | AD7: 599.696 | AE7: 600.002 | AF7: 600.411 | AG7: 0.000957279 | AH7: 0.000363442 | AI7: 0.380025 | AJ7: 0.379661 | AK7: 0.00117703 | AL7: 0.000447213 | AM7: 0.380398 | AN7: 0.379951 | AO7: 0.0012027 | AP7: 0.000458059 | AQ7: 0.381318 | AR7: 0.38086 | AS7: 0.0011419 | AT7: 0.000434326 | AU7: 0.38079 | AV7: 0.380355 | AW7: 0.0011003 | AX7: 0.000418067 | AY7: 0.380376 | AZ7: 0.379958
A8: 5 | B8: 599.774 | C8: 600.349 | D8: 599.571 | E8: 600.23 | F8: 599.9 | G8: 0.000501265 | H8: 0.000190218 | I8: 0.379667 | J8: 0.379477 | K8: 0.00113061 | L8: 0.000430107 | M8: 0.380852 | N8: 0.380422 | O8: 0.00101356 | P8: 0.000385599 | Q8: 0.380827 | R8: 0.380442 | S8: 0.000750298 | T8: 0.000285464 | U8: 0.380753 | V8: 0.380467 | W8: 0.00131768 | X8: 0.000500799 | Y8: 0.380562 | Z8: 0.380061 | AB8: 600.167 | AC8: 599.951 | AD8: 599.719 | AE8: 600.023 | AF8: 600.493 | AG8: 0.000999041 | AH8: 0.000379297 | AI8: 0.380041 | AJ8: 0.379661 | AK8: 0.000879715 | AL8: 0.000334249 | AM8: 0.380285 | AN8: 0.379951 | AO8: 0.00120392 | AP8: 0.000458526 | AQ8: 0.381318 | AR8: 0.38086 | AS8: 0.000842466 | AT8: 0.000320436 | AU8: 0.380676 | AV8: 0.380355 | AW8: 0.00137164 | AX8: 0.000521164 | AY8: 0.380479 | AZ8: 0.379958
A9: 6 | B9: 599.881 | C9: 600.32 | D9: 599.576 | E9: 600.169 | F9: 600.119 | G9: 0.00127956 | H9: 0.000485565 | I9: 0.379962 | J9: 0.379477 | K9: 0.00167672 | L9: 0.000637862 | M9: 0.38106 | N9: 0.380422 | O9: 0.00131574 | P9: 0.000500561 | Q9: 0.380942 | R9: 0.380442 | S9: 0.00113005 | T9: 0.000429949 | U9: 0.380897 | V9: 0.380467 | W9: 0.00175663 | X9: 0.000667625 | Y9: 0.380729 | Z9: 0.380061 | AB9: 600.201 | AC9: 599.979 | AD9: 599.802 | AE9: 600.044 | AF9: 600.493 | AG9: 0.00122368 | AH9: 0.000464585 | AI9: 0.380126 | AJ9: 0.379661 | AK9: 0.00175948 | AL9: 0.000668518 | AM9: 0.38062 | AN9: 0.379951 | AO9: 0.00174852 | AP9: 0.000665943 | AQ9: 0.381526 | AR9: 0.38086 | AS9: 0.0018463 | AT9: 0.000702249 | AU9: 0.381058 | AV9: 0.380355 | AW9: 0.00163425 | AX9: 0.000620949 | AY9: 0.380579 | AZ9: 0.379958
A10: 7 | B10: 600.114 | C10: 600.71 | D10: 599.853 | E10: 600.459 | F10: 600.071 | G10: 0.00134555 | H10: 0.000510606 | I10: 0.379987 | J10: 0.379477 | K10: 0.00157698 | L10: 0.000599917 | M10: 0.381022 | N10: 0.380422 | O10: 0.00171963 | P10: 0.00065422 | Q10: 0.381096 | R10: 0.380442 | S10: 0.00119213 | T10: 0.000453566 | U10: 0.380921 | V10: 0.380467 | W10: 0.00170946 | X10: 0.000649698 | Y10: 0.380711 | Z10: 0.380061 | AB10: 600.368 | AC10: 600.188 | AD10: 599.953 | AE10: 600.195 | AF10: 600.624 | AG10: 0.00125878 | AH10: 0.000477911 | AI10: 0.380139 | AJ10: 0.379661 | AK10: 0.00151284 | AL10: 0.000574806 | AM10: 0.380526 | AN10: 0.379951 | AO10: 0.00170969 | AP10: 0.000651153 | AQ10: 0.381511 | AR10: 0.38086 | AS10: 0.00168777 | AT10: 0.000641954 | AU10: 0.380997 | AV10: 0.380355 | AW10: 0.00162255 | AX10: 0.000616503 | AY10: 0.380575 | AZ10: 0.379958
A11: 8 | B11: 600.392 | C11: 600.889 | D11: 600.008 | E11: 600.622 | F11: 600.314 | G11: 0.0014701 | H11: 0.00055787 | I11: 0.380035 | J11: 0.379477 | K11: 0.00197537 | L11: 0.000751473 | M11: 0.381173 | N11: 0.380422 | O11: 0.00213446 | P11: 0.000812037 | Q11: 0.381254 | R11: 0.380442 | S11: 0.00127486 | T11: 0.000485042 | U11: 0.380952 | V11: 0.380467 | W11: 0.00217104 | X11: 0.000825127 | Y11: 0.380886 | Z11: 0.380061 | AB11: 600.528 | AC11: 600.441 | AD11: 600.174 | AE11: 600.439 | AF11: 600.723 | AG11: 0.00156915 | AH11: 0.000595746 | AI11: 0.380257 | AJ11: 0.379661 | AK11: 0.0012855 | AL11: 0.000488427 | AM11: 0.380439 | AN11: 0.379951 | AO11: 0.00174969 | AP11: 0.000666388 | AQ11: 0.381526 | AR11: 0.38086 | AS11: 0.00192545 | AT11: 0.000732355 | AU11: 0.381088 | AV11: 0.380355 | AW11: 0.00193705 | AX11: 0.000735998 | AY11: 0.380694 | AZ11: 0.379958
A12: 9 | B12: 600.395 | C12: 600.856 | D12: 600.445 | E12: 600.667 | F12: 600.459 | G12: 0.00152093 | H12: 0.000577156 | I12: 0.380054 | J12: 0.379477 | K12: 0.00200999 | L12: 0.000764642 | M12: 0.381187 | N12: 0.380422 | O12: 0.00200148 | P12: 0.000761446 | Q12: 0.381203 | R12: 0.380442 | S12: 0.00131329 | T12: 0.000499666 | U12: 0.380967 | V12: 0.380467 | W12: 0.00237278 | X12: 0.000901799 | Y12: 0.380963 | Z12: 0.380061 | AB12: 600.524 | AC12: 600.278 | AD12: 600.102 | AE12: 600.409 | AF12: 600.902 | AG12: 0.00157408 | AH12: 0.000597616 | AI12: 0.380259 | AJ12: 0.379661 | AK12: 0.00155255 | AL12: 0.000589895 | AM12: 0.380541 | AN12: 0.379951 | AO12: 0.00208432 | AP12: 0.000793835 | AQ12: 0.381654 | AR12: 0.38086 | AS12: 0.00209828 | AT12: 0.000798092 | AU12: 0.381154 | AV12: 0.380355 | AW12: 0.00227465 | AX12: 0.000864274 | AY12: 0.380823 | AZ12: 0.379958
A13: 10 | B13: 600.345 | C13: 600.718 | D13: 599.913 | E13: 600.397 | F13: 600.261 | G13: 0.00196083 | H13: 0.000744091 | I13: 0.380221 | J13: 0.379477 | K13: 0.00219601 | L13: 0.000835412 | M13: 0.381257 | N13: 0.380422 | O13: 0.0020394 | P13: 0.000775872 | Q13: 0.381217 | R13: 0.380442 | S13: 0.00196729 | T13: 0.000748491 | U13: 0.381216 | V13: 0.380467 | W13: 0.00302447 | X13: 0.00114948 | Y13: 0.381211 | Z13: 0.380061 | AB13: 600.425 | AC13: 600.354 | AD13: 600.098 | AE13: 600.27 | AF13: 600.625 | AG13: 0.00184131 | AH13: 0.000699074 | AI13: 0.38036 | AJ13: 0.379661 | AK13: 0.0019417 | AL13: 0.000737752 | AM13: 0.380689 | AN13: 0.379951 | AO13: 0.00236425 | AP13: 0.000900448 | AQ13: 0.38176 | AR13: 0.38086 | AS13: 0.00242138 | AT13: 0.000920984 | AU13: 0.381276 | AV13: 0.380355 | AW13: 0.0026168 | AX13: 0.000994276 | AY13: 0.380953 | AZ13: 0.379958
A14: 11 | B14: 600.637 | C14: 600.966 | D14: 600.217 | E14: 600.548 | F14: 600.691 | G14: 0.00221438 | H14: 0.000840305 | I14: 0.380317 | J14: 0.379477 | K14: 0.00239452 | L14: 0.000910929 | M14: 0.381333 | N14: 0.380422 | O14: 0.00275585 | P14: 0.00104844 | Q14: 0.38149 | R14: 0.380442 | S14: 0.00210327 | T14: 0.000800227 | U14: 0.381268 | V14: 0.380467 | W14: 0.00281372 | X14: 0.00106939 | Y14: 0.38113 | Z14: 0.380061 | AB14: 600.643 | AC14: 600.408 | AD14: 600.222 | AE14: 600.447 | AF14: 600.899 | AG14: 0.00206652 | AH14: 0.000784576 | AI14: 0.380446 | AJ14: 0.379661 | AK14: 0.00214535 | AL14: 0.000815127 | AM14: 0.380766 | AN14: 0.379951 | AO14: 0.00240077 | AP14: 0.000914359 | AQ14: 0.381774 | AR14: 0.38086 | AS14: 0.00243948 | AT14: 0.000927871 | AU14: 0.381283 | AV14: 0.380355 | AW14: 0.00267521 | AX14: 0.00101647 | AY14: 0.380975 | AZ14: 0.379958
